package assertk

/**
 * Assertions are run in a failure context which captures failures to report them.
 */
internal object FailureContext {
    internal var failure: Failure = SimpleFailure()

    /**
     * Run the given block of assertions in the given context. If we are already in a context a new one will not be
     * created.
     */
    fun <T> run(failure: Failure, f: () -> T): T {
        if (this.failure is SimpleFailure) {
            val tmp = this.failure
            this.failure = failure
            val result = f()
            this.failure = tmp
            failure()
            return result
        } else {
            return f()
        }
    }
}

internal interface Failure {
    /**
     * Record a failure. Depending on the implementation this may throw an exception or collect the failure for later.
     */
    fun fail(error: AssertionError)

    /**
     * Triggers any collected failures.
     */
    operator fun invoke() {
    }
}

/**
 * Failure that immediately thrown an exception.
 */
internal class SimpleFailure : Failure {
    override fun fail(error: AssertionError) {
        failWithNotInStacktrace(error)
    }
}

/**
 * Failure that collects all failures and displays them at once.
 */
internal class SoftFailure : Failure {
    private val failures: MutableList<AssertionError> = ArrayList()

    override fun fail(error: AssertionError) {
        failures.add(error)
    }

    override fun invoke() {
        if (!failures.isEmpty()) {
            fail(compositeErrorMessage(failures))
        }
    }

    private fun compositeErrorMessage(errors: List<AssertionError>): String {
        return if (errors.size == 1) {
            errors.first().message.orEmpty()
        } else {
            errors.joinToString(
                    prefix = "The following ${errors.size} assertions failed:\n",
                    transform = { "- ${it.message}" },
                    separator = "\n"
            )
        }
    }
}


/**
 * Fail the test with the given {@link AssertionError}.
 */
fun fail(error: AssertionError) {
    FailureContext.failure.fail(error)
}

/**
 * Fail the test with the given message.
 */
fun fail(message: String) {
    FailureContext.failure.fail(AssertionError(message))
}

@Suppress("NOTHING_TO_INLINE", "PLATFORM_CLASS_MAPPED_TO_KOTLIN")
private inline fun failWithNotInStacktrace(error: AssertionError): Nothing {
    val filtered = error.stackTrace
            .dropWhile { it.className.startsWith("assertk") }
            .toTypedArray()
    (error as java.lang.Throwable).stackTrace = filtered
    throw error
}
